Workbook

Sheet m14
A1: apellido | B1: nombre | C1: mail | D1: telefono | E1: dni | F1: rol | G1: clienteid
A2: DIAZ MATOS | B2: FABRICIO | C2: claudiodiaz79@hotmail.com | D2: 1158380934 | E2: 52446718 | F2: JUGADOR | G2: 2
A3: SCARDINO | B3: GIULIANO | C3: rominaguardino@hotmail.com | D3: 1159389208 | E3: 52447299 | F3: JUGADOR | G3: 2
A4: CARJUZA | B4: NEHUEN | C4: soniajudithpi@gmail.com | D4: 1168656753 | E4: 52450545 | F4: JUGADOR | G4: 2
A5: COMPIANO | B5: BENICIO | C5: mcompiano@gmail.com | D5: 1140256257 | E5: 52768029 | F5: JUGADOR | G5: 2
A6: GHIOLDI | B6: FEDERICO | C6: jdghioldi@gmail.com | D6: 1139381187 | E6: 52698211 | F6: JUGADOR | G6: 2
A7: ALBANO | B7: LUCIANO | C7: jus_alb2020@hotmail.com | D7: 1144405773 | E7: 52647514 | F7: JUGADOR | G7: 2
A8: ALBANO | B8: JOAQUIN | C8: jus_alb2020@hotmail.com | D8: 1144405773 | E8: 52647515 | F8: JUGADOR | G8: 2
A9: FERREYRA | B9: AARON | C9: soymariajosedelvalle@gmail.com | D9: 1133662100 | E9: 52186172 | F9: JUGADOR | G9: 2
A10: MURILLI | B10: VICENTE | C10: mariaceciliasauan@gmail.com | D10: 1167040308 | E10: 52704531 | F10: JUGADOR | G10: 2
A11: LENTINI | B11: SANTIAGO | D11: 1122611000 | E11: 52454977 | F11: JUGADOR | G11: 2
A12: GUTIERREZ | B12: LUCIANO | C12: ariel_dgut@hotmail.com | D12: 1121541140 | E12: 52453603 | F12: JUGADOR | G12: 2
A13: NICODELLA | B13: CLEMENTE | C13: lorenamadjian@gmail.com | D13: 1131688920 | E13: 52648585 | F13: JUGADOR | G13: 2
A14: FERNANDEZ | B14: MATEO | D14: 1122774958 | E14: 52448179 | F14: JUGADOR | G14: 2
A15: POLO | B15: NAZARENO | C15: arielpolo@gmail.com | D15: 1134403695 | E15: 52762298 | F15: JUGADOR | G15: 2
A16: REYES | B16: LUCAS | C16: alejandroreyes4@yahoo.com | D16: 1131963655 | E16: 52852332 | F16: JUGADOR | G16: 2
A17: DIEGUEZ | B17: CIRO | C17: sebastiangdieguez@gmail.com | D17: 1165390007 | E17: 53082019 | F17: JUGADOR | G17: 2
A18: RAMON VIÑAL | B18: LAUREANO | C18: pablosebastianramon@gmail.com | D18: 1122965826 | E18: 52439950 | F18: JUGADOR | G18: 2
A19: KALADJIAN | B19: JUAN MARTIN | C19: silvihapa@hotmail.com | D19: 1158581634 | E19: 52855867 | F19: JUGADOR | G19: 2
A20: CALSINA | B20: MATIAS | C20: shen.erik.mati@gmail.com | D20: 1167112783 | E20: 52137893 | F20: JUGADOR | G20: 2

Sheet persona_rows
A1: dni | B1: personaid | C1: timestamp | D1: nombre | E1: apellido | F1: telefono | G1: mail | H1: rol | I1: posicion | J1: clienteid | K1: fechanacimiento
B2: 24 | C2: 46162.423 | D2: Santiago | E2: Zanardo | G2: santiago.zanardo@gmail.com2 | H2: MANAGER
B3: 25 | C3: 46162.424 | D3: Admin | E3: Admin | G3: useradmin@club.com.ar
A4: 52446718 | B4: 26 | C4: 46162.487 | D4: CARJUZA | E4: NEHUEN | F4: 1158380934 | G4: claudiodiaz79@hotmail.com | H4: JUGADOR | I4: CENTRO | J4: 2
A5: 52446718 | B5: 27 | C5: 46162.491 | D5: FABRICIO | E5: DIAZ MATOS | F5: 1158380934 | G5: claudiodiaz79@hotmail.com | H5: JUGADOR | J5: 2
A6: 52447299 | B6: 28 | C6: 46162.491 | D6: GIULIANO | E6: SCARDINO | F6: 1159389208 | G6: rominaguardino@hotmail.com | H6: JUGADOR | J6: 2
A7: 52450545 | B7: 29 | C7: 46162.491 | D7: NEHUEN | E7: CARJUZA | F7: 1168656753 | G7: soniajudithpi@gmail.com | H7: JUGADOR | J7: 2
A8: 52768029 | B8: 30 | C8: 46162.491 | D8: BENICIO | E8: COMPIANO | F8: 1140256257 | G8: mcompiano@gmail.com | H8: JUGADOR | J8: 2
A9: 52698211 | B9: 31 | C9: 46162.491 | D9: FEDERICO | E9: GHIOLDI | F9: 1139381187 | G9: jdghioldi@gmail.com | H9: JUGADOR | J9: 2
A10: 52647514 | B10: 32 | C10: 46162.491 | D10: LUCIANO | E10: ALBANO | F10: 1144405773 | G10: jus_alb2020@hotmail.com | H10: JUGADOR | J10: 2
A11: 52647515 | B11: 33 | C11: 46162.491 | D11: JOAQUIN | E11: ALBANO | F11: 1144405773 | G11: jus_alb2020@hotmail.com | H11: JUGADOR | J11: 2 | K11: 41228
A12: 52186172 | B12: 34 | C12: 46162.491 | D12: AARON | E12: FERREYRA | F12: 1133662100 | G12: soymariajosedelvalle@gmail.com | H12: JUGADOR | J12: 2
A13: 52704531 | B13: 35 | C13: 46162.491 | D13: VICENTE | E13: MURILLI | F13: 1167040308 | G13: mariaceciliasauan@gmail.com | H13: JUGADOR | J13: 2
A14: 52454977 | B14: 36 | C14: 46162.491 | D14: SANTIAGO | E14: LENTINI | F14: 1122611000 | H14: JUGADOR | J14: 2
A15: 52453603 | B15: 37 | C15: 46162.491 | D15: LUCIANO | E15: GUTIERREZ | F15: 1121541140 | G15: ariel_dgut@hotmail.com | H15: JUGADOR | J15: 2
A16: 52648585 | B16: 38 | C16: 46162.491 | D16: CLEMENTE | E16: NICODELLA | F16: 1131688920 | G16: lorenamadjian@gmail.com | H16: JUGADOR | J16: 2
A17: 52448179 | B17: 39 | C17: 46162.491 | D17: MATEO | E17: FERNANDEZ | F17: 1122774958 | H17: JUGADOR | J17: 2 | K17: 41137
A18: 52762298 | B18: 40 | C18: 46162.491 | D18: NAZARENO | E18: POLO | F18: 1134403695 | G18: arielpolo@gmail.com | H18: JUGADOR | J18: 2
A19: 52852332 | B19: 41 | C19: 46162.491 | D19: LUCAS | E19: REYES | F19: 1131963655 | G19: alejandroreyes4@yahoo.com | H19: JUGADOR | J19: 2
A20: 53082019 | B20: 42 | C20: 46162.491 | D20: CIRO | E20: DIEGUEZ | F20: 1165390007 | G20: sebastiangdieguez@gmail.com | H20: JUGADOR | J20: 2
A21: 52439950 | B21: 43 | C21: 46162.491 | D21: LAUREANO | E21: RAMON VIÑAL | F21: 1122965826 | G21: pablosebastianramon@gmail.com | H21: JUGADOR | J21: 2
A22: 52855867 | B22: 44 | C22: 46162.491 | D22: JUAN MARTIN | E22: KALADJIAN | F22: 1158581634 | G22: silvihapa@hotmail.com | H22: JUGADOR | J22: 2
A23: 52137893 | B23: 45 | C23: 46162.491 | D23: MATIAS | E23: CALSINA | F23: 1167112783 | G23: shen.erik.mati@gmail.com | H23: JUGADOR | J23: 2
A24: 35270492 | B24: 46 | C24: 46162.532 | D24: Diego javier | E24: Alderete | H24: JUGADOR | J24: 2
A25: 46908023 | B25: 47 | C25: 46162.532 | D25: Tahiel | E25: Alegre | H25: JUGADOR | J25: 2
A26: 32674341 | B26: 48 | C26: 46162.532 | D26: Fernando Ariel | E26: Alonso Ferreyra | H26: JUGADOR | J26: 2
A27: 46915289 | B27: 49 | C27: 46162.532 | D27: Luciano | E27: Altobelli Capria | H27: JUGADOR | J27: 2
A28: 43720513 | B28: 50 | C28: 46162.532 | D28: Giuliano Hernan | E28: Andrade | H28: JUGADOR | J28: 2
A29: 45235320 | B29: 51 | C29: 46162.532 | D29: Alejandro | E29: Aranda | H29: JUGADOR | J29: 2
B30: 52 | C30: 46162.532 | D30: Marcos | E30: Astudillo | H30: JUGADOR | J30: 2
A31: 47344151 | B31: 53 | C31: 46162.532 | D31: Bruno | E31: Avila Diz | H31: JUGADOR | J31: 2
A32: 47295732 | B32: 54 | C32: 46162.532 | D32: Bautista | E32: Ayala | H32: JUGADOR | J32: 2
A33: 37611683 | B33: 55 | C33: 46162.532 | D33: Gonzalo Augusto | E33: Benjumeda | H33: JUGADOR | J33: 2
A34: 45926851 | B34: 56 | C34: 46162.532 | D34: Federico | E34: Bonafe | H34: JUGADOR | J34: 2
A35: 44484100 | B35: 57 | C35: 46162.532 | D35: Franco | E35: Bonanni | H35: JUGADOR | J35: 2
A36: 47029831 | B36: 58 | C36: 46162.532 | D36: Pablo | E36: Calabrese | H36: JUGADOR | J36: 2
A37: 45822370 | B37: 59 | C37: 46162.532 | D37: Agustín | E37: Calvo Langenheim | H37: JUGADOR | J37: 2
A38: 44158542 | B38: 60 | C38: 46162.532 | D38: Sebastian | E38: Calzon Heikel | H38: JUGADOR | J38: 2
A39: 41496855 | B39: 61 | C39: 46162.532 | D39: Jorge Francisco | E39: Cano | H39: JUGADOR | J39: 2
A40: 45571521 | B40: 62 | C40: 46162.532 | D40: Lucas | E40: Caprino | H40: JUGADOR | J40: 2
...

Sheet ps
A1: apellido | B1: nombre | C1: dni | D1: rol | E1: clienteid | H1: plantelid | I1: personaid
A2: Alderete | B2: Diego javier | C2: 35270492 | D2: JUGADOR | E2: 2 | F2: HOOKER | H2: 7 | I2: =+VLOOKUP(C2,persona_rows!A:B,2,FALSE) -> 46
A3: Alegre | B3: Tahiel | C3: 46908023 | D3: JUGADOR | E3: 2 | F3: WING | H3: 7 | I3: =+VLOOKUP(C3,persona_rows!A:B,2,FALSE) -> 47
A4: Alonso Ferreyra | B4: Fernando Ariel | C4: 32674341 | D4: JUGADOR | E4: 2 | F4: OCTAVO | H4: 7 | I4: =+VLOOKUP(C4,persona_rows!A:B,2,FALSE) -> 48
A5: Altobelli Capria | B5: Luciano | C5: 46915289 | D5: JUGADOR | E5: 2 | F5: HOOKER | H5: 7 | I5: =+VLOOKUP(C5,persona_rows!A:B,2,FALSE) -> 49
A6: Andrade | B6: Giuliano Hernan | C6: 43720513 | D6: JUGADOR | E6: 2 | F6: HOOKER | H6: 7 | I6: =+VLOOKUP(C6,persona_rows!A:B,2,FALSE) -> 50
A7: Aranda | B7: Alejandro | C7: 45235320 | D7: JUGADOR | E7: 2 | F7: ALA | H7: 7 | I7: =+VLOOKUP(C7,persona_rows!A:B,2,FALSE) -> 51
A8: Astudillo | B8: Marcos | D8: JUGADOR | E8: 2 | F8: PILARDER | H8: 7
A9: Avila Diz | B9: Bruno | C9: 47344151 | D9: JUGADOR | E9: 2 | F9: MEDIOSCR | H9: 7 | I9: =+VLOOKUP(C9,persona_rows!A:B,2,FALSE) -> 53
A10: Ayala | B10: Bautista | C10: 47295732 | D10: JUGADOR | E10: 2 | F10: OCTAVO | H10: 7 | I10: =+VLOOKUP(C10,persona_rows!A:B,2,FALSE) -> 54
A11: Benjumeda | B11: Gonzalo Augusto | C11: 37611683 | D11: JUGADOR | E11: 2 | F11: PILARDER | H11: 7 | I11: =+VLOOKUP(C11,persona_rows!A:B,2,FALSE) -> 55
A12: Bonafe | B12: Federico | C12: 45926851 | D12: JUGADOR | E12: 2 | F12: WING | H12: 7 | I12: =+VLOOKUP(C12,persona_rows!A:B,2,FALSE) -> 56
A13: Bonanni | B13: Franco | C13: 44484100 | D13: JUGADOR | E13: 2 | F13: ALA | H13: 7 | I13: =+VLOOKUP(C13,persona_rows!A:B,2,FALSE) -> 57
A14: Calabrese | B14: Pablo | C14: 47029831 | D14: JUGADOR | E14: 2 | F14: OCTAVO | H14: 7 | I14: =+VLOOKUP(C14,persona_rows!A:B,2,FALSE) -> 58
A15: Calvo Langenheim | B15: Agustín | C15: 45822370 | D15: JUGADOR | E15: 2 | F15: ALA | H15: 7 | I15: =+VLOOKUP(C15,persona_rows!A:B,2,FALSE) -> 59
A16: Calzon Heikel | B16: Sebastian | C16: 44158542 | D16: JUGADOR | E16: 2 | F16: CENTRO | H16: 7 | I16: =+VLOOKUP(C16,persona_rows!A:B,2,FALSE) -> 60
A17: Cano | B17: Jorge Francisco | C17: 41496855 | D17: JUGADOR | E17: 2 | F17: CENTRO | H17: 7 | I17: =+VLOOKUP(C17,persona_rows!A:B,2,FALSE) -> 61
A18: Caprino | B18: Lucas | C18: 45571521 | D18: JUGADOR | E18: 2 | H18: 7 | I18: =+VLOOKUP(C18,persona_rows!A:B,2,FALSE) -> 62
A19: Caracciolo | B19: Federico | C19: 43870592 | D19: JUGADOR | E19: 2 | F19: FULLBACK | H19: 7 | I19: =+VLOOKUP(C19,persona_rows!A:B,2,FALSE) -> 63
A20: Carpy | B20: Juan ignacio | C20: 39657307 | D20: JUGADOR | E20: 2 | F20: WING | H20: 7 | I20: =+VLOOKUP(C20,persona_rows!A:B,2,FALSE) -> 64
A21: Carugati | B21: Valentino | C21: 46209547 | D21: JUGADOR | E21: 2 | F21: ALA | H21: 7 | I21: =+VLOOKUP(C21,persona_rows!A:B,2,FALSE) -> 65
A22: Castro | B22: Sebastián | C22: 26046885 | D22: JUGADOR | E22: 2 | F22: APERTURA | H22: 7 | I22: =+VLOOKUP(C22,persona_rows!A:B,2,FALSE) -> 66
A23: Cerdá | B23: Mateo | C23: 46211875 | D23: JUGADOR | E23: 2 | F23: ALA | H23: 7 | I23: =+VLOOKUP(C23,persona_rows!A:B,2,FALSE) -> 67
A24: Cicatiello | B24: Valentín | C24: 42340901 | D24: JUGADOR | E24: 2 | F24: SEGUNDA | H24: 7 | I24: =+VLOOKUP(C24,persona_rows!A:B,2,FALSE) -> 68
A25: Colque | B25: Juan Pablo | C25: 36359940 | D25: JUGADOR | E25: 2 | F25: ALA | H25: 7 | I25: =+VLOOKUP(C25,persona_rows!A:B,2,FALSE) -> 69
A26: Commatteo | B26: Federico Martin | C26: 38455371 | D26: JUGADOR | E26: 2 | F26: HOOKER | H26: 7 | I26: =+VLOOKUP(C26,persona_rows!A:B,2,FALSE) -> 70
A27: Copello | B27: Pedro | C27: 35973835 | D27: JUGADOR | E27: 2 | F27: MEDIOSCR | H27: 7 | I27: =+VLOOKUP(C27,persona_rows!A:B,2,FALSE) -> 71
A28: Cosio | B28: Mauro | C28: 35960229 | D28: JUGADOR | E28: 2 | H28: 7 | I28: =+VLOOKUP(C28,persona_rows!A:B,2,FALSE) -> 72
A29: Cristobal Albornoz | B29: Ramiro | C29: 46210569 | D29: JUGADOR | E29: 2 | F29: WING | H29: 7 | I29: =+VLOOKUP(C29,persona_rows!A:B,2,FALSE) -> 73
A30: Dinatolo | B30: Mariano | C30: 38710028 | D30: JUGADOR | E30: 2 | F30: APERTURA | H30: 7 | I30: =+VLOOKUP(C30,persona_rows!A:B,2,FALSE) -> 74
A31: Eaton | B31: Matias | C31: 35793403 | D31: JUGADOR | E31: 2 | F31: OCTAVO | H31: 7 | I31: =+VLOOKUP(C31,persona_rows!A:B,2,FALSE) -> 75
A32: Ertola | B32: Tomas | C32: 46213466 | D32: JUGADOR | E32: 2 | F32: CENTRO | H32: 7 | I32: =+VLOOKUP(C32,persona_rows!A:B,2,FALSE) -> 76
A33: Espinal | B33: Geronimo | C33: 47170638 | D33: JUGADOR | E33: 2 | F33: CENTRO | H33: 7 | I33: =+VLOOKUP(C33,persona_rows!A:B,2,FALSE) -> 77
A34: Fernandez | B34: Lucas | C34: 44729576 | D34: JUGADOR | E34: 2 | F34: CENTRO | H34: 7 | I34: =+VLOOKUP(C34,persona_rows!A:B,2,FALSE) -> 78
A35: Ferreyro | B35: Ignacio | C35: 42821910 | D35: JUGADOR | E35: 2 | F35: OCTAVO | H35: 7 | I35: =+VLOOKUP(C35,persona_rows!A:B,2,FALSE) -> 79
A36: Ferreyro | B36: Santino | C36: 45686803 | D36: JUGADOR | E36: 2 | F36: WING | H36: 7 | I36: =+VLOOKUP(C36,persona_rows!A:B,2,FALSE) -> 80
A37: Filippini | B37: Bautista | C37: 42013957 | D37: JUGADOR | E37: 2 | F37: MEDIOSCR | H37: 7 | I37: =+VLOOKUP(C37,persona_rows!A:B,2,FALSE) -> 81
A38: Fuhr | B38: Ignacio | C38: 43010600 | D38: JUGADOR | E38: 2 | F38: WING | H38: 7 | I38: =+VLOOKUP(C38,persona_rows!A:B,2,FALSE) -> 82
A39: Giacopetti | B39: Salvador | C39: 45753658 | D39: JUGADOR | E39: 2 | F39: WING | H39: 7 | I39: =+VLOOKUP(C39,persona_rows!A:B,2,FALSE) -> 83
A40: Giudice | B40: Dante | C40: 47127274 | D40: JUGADOR | E40: 2 | F40: WING | H40: 7 | I40: =+VLOOKUP(C40,persona_rows!A:B,2,FALSE) -> 84
...

Sheet Hoja2
A1: dni
A2: 35270492 | B2: HOOKER | C2: =+CONCATENATE("update persona set posicion = '",B2,"' where dni = '",A2,"';") -> update persona set posicion = 'HOOKER' where dni = '35270492';
A3: 46908023 | B3: WING | C3: =+CONCATENATE("update persona set posicion = '",B3,"' where dni = '",A3,"';") -> update persona set posicion = 'WING' where dni = '46908023';
A4: 32674341 | B4: OCTAVO | C4: =+CONCATENATE("update persona set posicion = '",B4,"' where dni = '",A4,"';") -> update persona set posicion = 'OCTAVO' where dni = '32674341';
A5: 46915289 | B5: HOOKER | C5: =+CONCATENATE("update persona set posicion = '",B5,"' where dni = '",A5,"';") -> update persona set posicion = 'HOOKER' where dni = '46915289';
A6: 43720513 | B6: HOOKER | C6: =+CONCATENATE("update persona set posicion = '",B6,"' where dni = '",A6,"';") -> update persona set posicion = 'HOOKER' where dni = '43720513';
A7: 45235320 | B7: ALA | C7: =+CONCATENATE("update persona set posicion = '",B7,"' where dni = '",A7,"';") -> update persona set posicion = 'ALA' where dni = '45235320';
B8: PILARDER | C8: =+CONCATENATE("update persona set posicion = '",B8,"' where dni = '",A8,"';") -> update persona set posicion = 'PILARDER' where dni = '';
A9: 47344151 | B9: MEDIOSCR | C9: =+CONCATENATE("update persona set posicion = '",B9,"' where dni = '",A9,"';") -> update persona set posicion = 'MEDIOSCR' where dni = '47344151';
A10: 47295732 | B10: OCTAVO | C10: =+CONCATENATE("update persona set posicion = '",B10,"' where dni = '",A10,"';") -> update persona set posicion = 'OCTAVO' where dni = '47295732';
A11: 37611683 | B11: PILARDER | C11: =+CONCATENATE("update persona set posicion = '",B11,"' where dni = '",A11,"';") -> update persona set posicion = 'PILARDER' where dni = '37611683';
A12: 45926851 | B12: WING | C12: =+CONCATENATE("update persona set posicion = '",B12,"' where dni = '",A12,"';") -> update persona set posicion = 'WING' where dni = '45926851';
A13: 44484100 | B13: ALA | C13: =+CONCATENATE("update persona set posicion = '",B13,"' where dni = '",A13,"';") -> update persona set posicion = 'ALA' where dni = '44484100';
A14: 47029831 | B14: OCTAVO | C14: =+CONCATENATE("update persona set posicion = '",B14,"' where dni = '",A14,"';") -> update persona set posicion = 'OCTAVO' where dni = '47029831';
A15: 45822370 | B15: ALA | C15: =+CONCATENATE("update persona set posicion = '",B15,"' where dni = '",A15,"';") -> update persona set posicion = 'ALA' where dni = '45822370';
A16: 44158542 | B16: CENTRO | C16: =+CONCATENATE("update persona set posicion = '",B16,"' where dni = '",A16,"';") -> update persona set posicion = 'CENTRO' where dni = '44158542';
A17: 41496855 | B17: CENTRO | C17: =+CONCATENATE("update persona set posicion = '",B17,"' where dni = '",A17,"';") -> update persona set posicion = 'CENTRO' where dni = '41496855';
A18: 45571521 | C18: =+CONCATENATE("update persona set posicion = '",B18,"' where dni = '",A18,"';") -> update persona set posicion = '' where dni = '45571521';
A19: 43870592 | B19: FULLBACK | C19: =+CONCATENATE("update persona set posicion = '",B19,"' where dni = '",A19,"';") -> update persona set posicion = 'FULLBACK' where dni = '43870592';
A20: 39657307 | B20: WING | C20: =+CONCATENATE("update persona set posicion = '",B20,"' where dni = '",A20,"';") -> update persona set posicion = 'WING' where dni = '39657307';
A21: 46209547 | B21: ALA | C21: =+CONCATENATE("update persona set posicion = '",B21,"' where dni = '",A21,"';") -> update persona set posicion = 'ALA' where dni = '46209547';
A22: 26046885 | B22: APERTURA | C22: =+CONCATENATE("update persona set posicion = '",B22,"' where dni = '",A22,"';") -> update persona set posicion = 'APERTURA' where dni = '26046885';
A23: 46211875 | B23: ALA | C23: =+CONCATENATE("update persona set posicion = '",B23,"' where dni = '",A23,"';") -> update persona set posicion = 'ALA' where dni = '46211875';
A24: 42340901 | B24: SEGUNDA | C24: =+CONCATENATE("update persona set posicion = '",B24,"' where dni = '",A24,"';") -> update persona set posicion = 'SEGUNDA' where dni = '42340901';
A25: 36359940 | B25: ALA | C25: =+CONCATENATE("update persona set posicion = '",B25,"' where dni = '",A25,"';") -> update persona set posicion = 'ALA' where dni = '36359940';
A26: 38455371 | B26: HOOKER | C26: =+CONCATENATE("update persona set posicion = '",B26,"' where dni = '",A26,"';") -> update persona set posicion = 'HOOKER' where dni = '38455371';
A27: 35973835 | B27: MEDIOSCR | C27: =+CONCATENATE("update persona set posicion = '",B27,"' where dni = '",A27,"';") -> update persona set posicion = 'MEDIOSCR' where dni = '35973835';
A28: 35960229 | C28: =+CONCATENATE("update persona set posicion = '",B28,"' where dni = '",A28,"';") -> update persona set posicion = '' where dni = '35960229';
A29: 46210569 | B29: WING | C29: =+CONCATENATE("update persona set posicion = '",B29,"' where dni = '",A29,"';") -> update persona set posicion = 'WING' where dni = '46210569';
A30: 38710028 | B30: APERTURA | C30: =+CONCATENATE("update persona set posicion = '",B30,"' where dni = '",A30,"';") -> update persona set posicion = 'APERTURA' where dni = '38710028';
A31: 35793403 | B31: OCTAVO | C31: =+CONCATENATE("update persona set posicion = '",B31,"' where dni = '",A31,"';") -> update persona set posicion = 'OCTAVO' where dni = '35793403';
A32: 46213466 | B32: CENTRO | C32: =+CONCATENATE("update persona set posicion = '",B32,"' where dni = '",A32,"';") -> update persona set posicion = 'CENTRO' where dni = '46213466';
A33: 47170638 | B33: CENTRO | C33: =+CONCATENATE("update persona set posicion = '",B33,"' where dni = '",A33,"';") -> update persona set posicion = 'CENTRO' where dni = '47170638';
A34: 44729576 | B34: CENTRO | C34: =+CONCATENATE("update persona set posicion = '",B34,"' where dni = '",A34,"';") -> update persona set posicion = 'CENTRO' where dni = '44729576';
A35: 42821910 | B35: OCTAVO | C35: =+CONCATENATE("update persona set posicion = '",B35,"' where dni = '",A35,"';") -> update persona set posicion = 'OCTAVO' where dni = '42821910';
A36: 45686803 | B36: WING | C36: =+CONCATENATE("update persona set posicion = '",B36,"' where dni = '",A36,"';") -> update persona set posicion = 'WING' where dni = '45686803';
A37: 42013957 | B37: MEDIOSCR | C37: =+CONCATENATE("update persona set posicion = '",B37,"' where dni = '",A37,"';") -> update persona set posicion = 'MEDIOSCR' where dni = '42013957';
A38: 43010600 | B38: WING | C38: =+CONCATENATE("update persona set posicion = '",B38,"' where dni = '",A38,"';") -> update persona set posicion = 'WING' where dni = '43010600';
A39: 45753658 | B39: WING | C39: =+CONCATENATE("update persona set posicion = '",B39,"' where dni = '",A39,"';") -> update persona set posicion = 'WING' where dni = '45753658';
A40: 47127274 | B40: WING | C40: =+CONCATENATE("update persona set posicion = '",B40,"' where dni = '",A40,"';") -> update persona set posicion = 'WING' where dni = '47127274';
...
